[2024-07-30T09:54:01.702+0000] {local_task_job_runner.py:120} INFO - ::group::Pre task execution logs
[2024-07-30T09:54:01.737+0000] {taskinstance.py:2076} INFO - Dependencies all met for dep_context=non-requeueable deps ti=<TaskInstance: pipelinev1.stage_logs_task manual__2024-07-30T09:53:59.557007+00:00 [queued]>
[2024-07-30T09:54:01.749+0000] {taskinstance.py:2076} INFO - Dependencies all met for dep_context=requeueable deps ti=<TaskInstance: pipelinev1.stage_logs_task manual__2024-07-30T09:53:59.557007+00:00 [queued]>
[2024-07-30T09:54:01.750+0000] {taskinstance.py:2306} INFO - Starting attempt 1 of 1
[2024-07-30T09:54:01.832+0000] {taskinstance.py:2330} INFO - Executing <Task(StageToPostgresOperator): stage_logs_task> on 2024-07-30 09:53:59.557007+00:00
[2024-07-30T09:54:01.838+0000] {logging_mixin.py:188} WARNING - /home/***/.local/lib/python3.12/site-packages/***/task/task_runner/standard_task_runner.py:61 DeprecationWarning: This process (pid=1292) is multi-threaded, use of fork() may lead to deadlocks in the child.
[2024-07-30T09:54:01.840+0000] {standard_task_runner.py:63} INFO - Started process 1295 to run task
[2024-07-30T09:54:01.838+0000] {standard_task_runner.py:90} INFO - Running: ['***', 'tasks', 'run', 'pipelinev1', 'stage_logs_task', 'manual__2024-07-30T09:53:59.557007+00:00', '--job-id', '48', '--raw', '--subdir', 'DAGS_FOLDER/pipeline_dag.py', '--cfg-path', '/tmp/tmpkaa0hiv4']
[2024-07-30T09:54:01.840+0000] {standard_task_runner.py:91} INFO - Job 48: Subtask stage_logs_task
[2024-07-30T09:54:01.940+0000] {task_command.py:426} INFO - Running <TaskInstance: pipelinev1.stage_logs_task manual__2024-07-30T09:53:59.557007+00:00 [running]> on host 6ec5d930b7c6
[2024-07-30T09:54:02.131+0000] {taskinstance.py:2648} INFO - Exporting env vars: AIRFLOW_CTX_DAG_OWNER='***' AIRFLOW_CTX_DAG_ID='pipelinev1' AIRFLOW_CTX_TASK_ID='stage_logs_task' AIRFLOW_CTX_EXECUTION_DATE='2024-07-30T09:53:59.557007+00:00' AIRFLOW_CTX_TRY_NUMBER='1' AIRFLOW_CTX_DAG_RUN_ID='manual__2024-07-30T09:53:59.557007+00:00'
[2024-07-30T09:54:02.132+0000] {taskinstance.py:430} INFO - ::endgroup::
[2024-07-30T09:54:02.163+0000] {base.py:84} INFO - Using connection ID 'minio_conn' for task execution.
[2024-07-30T09:54:02.164+0000] {connection_wrapper.py:384} INFO - AWS Connection (conn_id='minio_conn', conn_type='aws') credentials retrieved from login and password.
[2024-07-30T09:54:02.217+0000] {taskinstance.py:441} INFO - ::group::Post task execution logs
[2024-07-30T09:54:02.218+0000] {taskinstance.py:2905} ERROR - Task failed with exception
Traceback (most recent call last):
  File "/home/airflow/.local/lib/python3.12/site-packages/airflow/models/taskinstance.py", line 465, in _execute_task
    result = _execute_callable(context=context, **execute_callable_kwargs)
             ^^^^^^^^^^^^^^^^^^^^^^^^^^^^^^^^^^^^^^^^^^^^^^^^^^^^^^^^^^^^^
  File "/home/airflow/.local/lib/python3.12/site-packages/airflow/models/taskinstance.py", line 432, in _execute_callable
    return execute_callable(context=context, **execute_callable_kwargs)
           ^^^^^^^^^^^^^^^^^^^^^^^^^^^^^^^^^^^^^^^^^^^^^^^^^^^^^^^^^^^^
  File "/home/airflow/.local/lib/python3.12/site-packages/airflow/models/baseoperator.py", line 401, in wrapper
    return func(self, *args, **kwargs)
           ^^^^^^^^^^^^^^^^^^^^^^^^^^^
  File "/opt/airflow/plugins/operators/stage_postgresql_operator.py", line 33, in execute
    objects = client.list_objects(self.s3_bucket, prefix=self.s3_prefix, recursive=True) if self.s3_prefix else [client.stat_object(self.s3_bucket, formatted_s3_key)]
                                                                                                                 ^^^^^^^^^^^^^^^^^^^^^^^^^^^^^^^^^^^^^^^^^^^^^^^^^^^^
  File "/home/airflow/.local/lib/python3.12/site-packages/minio/api.py", line 2043, in stat_object
    response = self._execute(
               ^^^^^^^^^^^^^^
  File "/home/airflow/.local/lib/python3.12/site-packages/minio/api.py", line 440, in _execute
    return self._url_open(
           ^^^^^^^^^^^^^^^
  File "/home/airflow/.local/lib/python3.12/site-packages/minio/api.py", line 423, in _url_open
    raise response_error
minio.error.S3Error: S3 operation failed; code: NoSuchKey, message: Object does not exist, resource: /udacity-dend/data/log_data/2018/11/2024-07-30-events.json, request_id: 17E6F4F55F02A1DF, host_id: dd9025bab4ad464b049177c95eb6ebf374d3b3fd1af9251148b658df7ac2e3e8, bucket_name: udacity-dend, object_name: data/log_data/2018/11/2024-07-30-events.json
[2024-07-30T09:54:02.241+0000] {taskinstance.py:1206} INFO - Marking task as FAILED. dag_id=pipelinev1, task_id=stage_logs_task, run_id=manual__2024-07-30T09:53:59.557007+00:00, execution_date=20240730T095359, start_date=20240730T095401, end_date=20240730T095402
[2024-07-30T09:54:02.402+0000] {standard_task_runner.py:110} ERROR - Failed to execute job 48 for task stage_logs_task (S3 operation failed; code: NoSuchKey, message: Object does not exist, resource: /udacity-dend/data/log_data/2018/11/2024-07-30-events.json, request_id: 17E6F4F55F02A1DF, host_id: dd9025bab4ad464b049177c95eb6ebf374d3b3fd1af9251148b658df7ac2e3e8, bucket_name: udacity-dend, object_name: data/log_data/2018/11/2024-07-30-events.json; 1295)
[2024-07-30T09:54:02.416+0000] {local_task_job_runner.py:240} INFO - Task exited with return code 1
[2024-07-30T09:54:02.456+0000] {taskinstance.py:3503} INFO - 0 downstream tasks scheduled from follow-on schedule check
[2024-07-30T09:54:02.516+0000] {local_task_job_runner.py:222} INFO - ::endgroup::
